<?xml version='1.0' encoding='utf-8'?>
<robot name="robot">

    <material name='white'>
        <color rgba="1.0 1.0 1.0 1.0"/>
    </material>

    <material name='black'>
        <color rgba="0.0 0.0 0.0 1.0"/>
    </material>

    <link name="base_link">
        <inertial>
            <origin xyz="0.0038662210655893464 0.0 0.052675337982169175" rpy="0.0 0.0 0.0" />
            <mass value="1.713155401009962" />
            <inertia ixx="0.0584527227543141" iyy="0.06191909363698124" izz="0.10992638017861338" ixy="0.0" iyz="0.0" ixz="-0.002306589723332078" />
        </inertial>
        <visual name="base_link_visual">
            <origin xyz="0.0 0.0 0.0" rpy="0.0 0.0 0.0" />
            <geometry>
                <mesh filename="file://$(find robot)/meshes/base_link.stl" scale="0.001 0.001 0.001" />
            </geometry>
            <material name='white'>
            </material>
        </visual>
        <collision name="base_link_collision">
            <origin xyz="0.0 0.0 0.0" rpy="0.0 0.0 0.0" />
            <geometry>
                <mesh filename="file://$(find robot)/meshes/base_link.stl" scale="0.001 0.001 0.001" />
            </geometry>
        </collision>
    </link>

    <gazebo reference="base_link">
        <material>Gazebo/White</material>
        <mu1 value="0.001"/>
        <mu2 value="0.001"/>
    </gazebo>

    <link name="right_wheel">
        <inertial>
            <origin xyz="5.7900231001220315e-18 0.0 0.012500000000000053" rpy="0.0 -0.0 0.0" />
            <mass value="0.15413438956674914" />
            <inertia ixx="0.0010436182626914897" iyy="0.0010436182626915452" izz="0.0019266798695843383" ixy="2.677325028344055e-19" iyz="1.734723475976807e-18" ixz="-1.7179502265207697e-18" />
        </inertial>
        <visual name="right_wheel_visual">
            <origin xyz="0.0 0.05 0.12500000000000003" rpy="1.5707963267948966 -0.0 0.0" />
            <geometry>
                <mesh filename="file://$(find robot)/meshes/right_wheel.stl" scale="0.001 0.001 0.001" />
            </geometry>
            <material name='black'>
            </material>
        </visual>
        <collision name="right_wheel_collision">
            <origin xyz="0.0 0.05 0.12500000000000003" rpy="1.5707963267948966 -0.0 0.0" />
            <geometry>
                <mesh filename="file://$(find robot)/meshes/right_wheel.stl" scale="0.001 0.001 0.001" />
            </geometry>
        </collision>
    </link>

    <gazebo reference="right_wheel">
        <material>Gazebo/Black</material>
    </gazebo>

    <link name="left_wheel">
        <inertial>
            <origin xyz="5.7900231001220315e-18 0.0 0.012500000000000018" rpy="0.0 -0.0 0.0" />
            <mass value="0.15413438956674914" />
            <inertia ixx="0.0010436182626914932" iyy="0.0010436182626915522" izz="0.0019266798695843383" ixy="2.677325028344058e-19" iyz="0.0" ixz="1.5394618912978329e-18" />
        </inertial>
        <visual name="left_wheel_visual">
            <origin xyz="0.0 0.05 -0.1" rpy="1.5707963267948966 -0.0 0.0" />
            <geometry>
                <mesh filename="file://$(find robot)/meshes/left_wheel.stl" scale="0.001 0.001 0.001" />
            </geometry>
            <material name='black'>
            </material>
        </visual>
        <collision name="left_wheel_collision">
            <origin xyz="0.0 0.05 -0.1" rpy="1.5707963267948966 -0.0 0.0" />
            <geometry>
                <mesh filename="file://$(find robot)/meshes/left_wheel.stl" scale="0.001 0.001 0.001" />
            </geometry>
        </collision>
    </link>

    <gazebo reference="left_wheel">
        <material>Gazebo/Black</material>
    </gazebo>   

    <joint name="base_link_Revolute-1" type="continuous">
        <origin xyz="0.0 0.1 0.05" rpy="-1.5707963267948966 -0.0 0.0" />
        <parent link="base_link" />
        <child link="left_wheel" />
        <axis xyz="0.0 0.0 1.0" />
    </joint>
    
    <joint name="base_link_Revolute-2" type="continuous">
        <origin xyz="0.0 -0.1 0.05" rpy="1.5707963267948966 -0.0 0.0" />
        <parent link="base_link" />
        <child link="right_wheel" />
        <axis xyz="0.0 0.0 -1.0" />
    </joint>
    
</robot>